<robot name="edo_description">
        
    <link name="world" />

    <joint name="world_base_joint" type="fixed">
      <parent link="world" />
      <child link="base_link" />
    </joint>

    <link name="base_link">
        <inertial>
            <origin xyz="0.0617583602130883 0.437262464550775 -0.00395442197852672" rpy="0 0 0" />
            <mass value="0.55942338762368" />
            <inertia ixx="0.1" ixy="0" ixz="0" iyy="0.01" iyz="0" izz="0.01" />
        </inertial>

        <visual>
            <origin xyz="0 0 0" rpy="0 0 0" />
            <geometry>
                <mesh filename="package://edo_description/meshes/base_link.STL" />
            </geometry>
            <material name="">
                <color rgba="0.792156862745098 0.819607843137255 0.933333333333333 1" />
            </material>
        </visual>
        <collision>
            <origin xyz="0 0 0" rpy="0 0 0" />
            <geometry>
                <mesh filename="package://edo_description/meshes/base_link.STL" />
            </geometry>
        </collision>
    </link>

    <joint name="joint_1" type="revolute">
        <origin xyz="0.057188 0.0059831 0.13343" rpy="1.5708 6.9389E-16 -3.1416" />
        <parent link="base_link" />
        <child link="link_1" />
        <axis xyz="0 1 0" />
        <limit effort="1000000" lower="-3.1416" upper="3.1416" velocity="100" />
        <dynamics damping="25" friction="0.2"/>
    </joint>

    <link name="link_1">
        
        <inertial>
            <origin xyz="-0.00457048841401064 0.303831811417004 -0.00202866410579916" rpy="0 0 0" />
            <mass value="0.55942338762368" />
            <inertia ixx="0.1" ixy="0" ixz="0" iyy="0.01" iyz="0" izz="0.01" />
        </inertial>

        <visual>
            <origin xyz="0 0 0" rpy="0 0 0" />
            <geometry>
                <mesh filename="package://edo_description/meshes/link_1.STL" />
            </geometry>
            <material name="">
                <color rgba="0.792156862745098 0.819607843137255 0.933333333333333 1" />
            </material>
        </visual>
        <collision>
            <origin xyz="0 0 0" rpy="0 0 0" />
            <geometry>
                <mesh filename="package://edo_description/meshes/link_1.STL" />
            </geometry>
        </collision>
    </link>

    <link name="link_2">
        
        <inertial>
            <origin xyz="-0.0168406485709407 0.071318237296396 -0.0876822373080704" rpy="0 0 0" />
            <mass value="0.5" />
            <inertia ixx="0.0122070242873091" ixy="0" ixz="0" iyy="0.01" iyz="0" izz="0.01" />
        </inertial>

        <visual>
            <origin xyz="0 0 0" rpy="0 0 0" />
            <geometry>
                <mesh filename="package://edo_description/meshes/link_2.STL" />
            </geometry>
            <material name="">
                <color rgba="0.792156862745098 0.819607843137255 0.933333333333333 1" />
            </material>
        </visual>
        <collision>
            <origin xyz="0 0 0" rpy="0 0 0" />
            <geometry>
                <mesh filename="package://edo_description/meshes/link_2.STL" />
            </geometry>
        </collision>
    </link>

    <joint name="joint_2" type="revolute">
        <origin xyz="0 0.18967 0" rpy="0.94237 -0.4634 -0.11653" />
        <parent link="link_1" />
        <child link="link_2" />
        <axis xyz="-0.88847 0.2908 0.35504" />
        <limit effort="1000000" lower="-3.1416" upper="3.1416" velocity="100" />
        <dynamics damping="25" friction="0.2"/>
    </joint>

    <link name="link_3">
        
        <inertial>
            <origin xyz="0.00457048841401063 0.0962524890074447 0.00395442197852662" rpy="0 0 0" />
            <mass value="0.5785942338762368" />
            <inertia ixx="0.0123841200738068" ixy="0" ixz="0" iyy="0.01" iyz="0" izz="0.01" />
        </inertial>

        <visual>
            <origin xyz="0 0 0" rpy="0 0 0" />
            <geometry>
                <mesh filename="package://edo_description/meshes/link_3.STL" />
            </geometry>
            <material name="">
                <color rgba="0.792156862745098 0.819607843137255 0.933333333333333 1" />
            </material>
        </visual>
        <collision>
            <origin xyz="0 0 0" rpy="0 0 0" />
            <geometry>
                <mesh filename="package://edo_description/meshes/link_3.STL" />
            </geometry>
        </collision>
    </link>

    <joint name="joint_3" type="revolute">
        <origin xyz="-0.024558 0.12737 -0.16578" rpy="0.97336 -0.36296 2.8253" />
        <parent link="link_2" />
        <child link="link_3" />
        <axis xyz="1 0 0" />
        <limit effort="1000000" lower="-3.1416" upper="3.1416" velocity="100" />
        <dynamics damping="25" friction="0.2"/>
    </joint>

    <link name="link_4">
        
        <inertial>
            <origin xyz="-0.00422951158597114 -0.00395442197852627 0.255057059248813" rpy="0 0 0" />
            <mass value="0.5785942338762368" />
            <inertia ixx="0.0123841200738068" ixy="0" ixz="0" iyy="0.01" iyz="0" izz="0.01" />
        </inertial>

        <visual>
            <origin xyz="0 0 0" rpy="0 0 0" />
            <geometry>
                <mesh filename="package://edo_description/meshes/link_4.STL" />
            </geometry>
            <material name="">
                <color rgba="0.792156862745098 0.819607843137255 0.933333333333333 1" />
            </material>
        </visual>
        <collision>
            <origin xyz="0 0 0" rpy="0 0 0" />
            <geometry>
                <mesh filename="package://edo_description/meshes/link_4.STL" />
            </geometry>
        </collision>
    </link>

    <joint name="joint_4" type="revolute">
        <origin xyz="0.0088 -0.1588 0" rpy="-1.5708 0 0" />
        <parent link="link_3" />
        <child link="link_4" />
        <axis xyz="0 0 -1" />
        <limit effort="1000000" lower="-3.1416" upper="3.1416" velocity="100" />
        <dynamics damping="25" friction="0.2"/>
    </joint>

    <link name="link_5">
        
        <inertial>
            <origin xyz="0.00422951158596777 -0.00395442197852616 -0.360352489007445" rpy="0 0 0" />
            <mass value="0.5785942338762368" />
            <inertia ixx="0.0123841200738068" ixy="0" ixz="0" iyy="0.01" iyz="0" izz="0.01" />
        </inertial>

        <visual>
            <origin xyz="0 0 0" rpy="0 0 0" />
            <geometry>
                <mesh filename="package://edo_description/meshes/link_5.STL" />
            </geometry>
            <material name="">
                <color rgba="0.792156862745098 0.819607843137255 0.933333333333333 1" />
            </material>
        </visual>
        <collision>
            <origin xyz="0 0 0" rpy="0 0 0" />
            <geometry>
                <mesh filename="package://edo_description/meshes/link_5.STL" />
            </geometry>
        </collision>
    </link>

    <joint name="joint_5" type="revolute">
        <origin xyz="0 0 -0.1053" rpy="3.1416 1.1102E-14 3.1416" />
        <parent link="link_4" />
        <child link="link_5" />
        <axis xyz="-1 0 0" />
        <limit effort="1000000" lower="-3.1416" upper="3.1416" velocity="100" />
        <dynamics damping="25" friction="0.2"/>
    </joint>

    <link name="link_6">
        
        <inertial>
            <origin xyz="1.10581233290358E-05 -0.00932339385603209 6.35624315718574E-06" rpy="0 0 0" />
            <mass value="0.5279702497322662" />
            <inertia ixx="0.01" ixy="0" ixz="0" iyy="0.01" iyz="0" izz="0.01" />
        </inertial>

        <visual>
            <origin xyz="0 0 0" rpy="0 0 0" />
            <geometry>
                <mesh filename="package://edo_description/meshes/link_6.STL" />
            </geometry>
            <material name="">
                <color rgba="0.792156862745098 0.819607843137255 0.933333333333333 1" />
            </material>
        </visual>
        <collision>
            <origin xyz="0 0 0" rpy="0 0 0" />
            <geometry>
                <mesh filename="package://edo_description/meshes/link_6.STL" />
            </geometry>
        </collision>
    </link>

    <joint name="joint_6" type="revolute">
        <origin xyz="-0.0039 0 0.1636" rpy="-1.5708 1.249E-14 0" />
        <parent link="link_5" />
        <child link="link_6" />
        <axis xyz="0 -1 0" />
        <limit effort="1000000" lower="-3.1416" upper="3.1416" velocity="100" />
        <dynamics damping="25" friction="0.2"/>
    </joint>

    <link name="link_enf">
        <inertial>
      <origin
        xyz="0 0 0"
        rpy="0 0 0" />
      <mass value="0.5279702497322662" />
      <inertia
        ixx="0.01"
        ixy="0"
        ixz="0"
        iyy="0.01"
        iyz="0"
        izz="0.01" />
        </inertial>
      <visual>
        <origin
          xyz="0 0 0"
          rpy="1.57 0 0" />
        <geometry>
          <mesh
            filename="package://edo_description/meshes/cylinder.STL" />
        </geometry>
        <material
          name="">
          <color
            rgba="0.792156862745098 0.819607843137255 0.933333333333333 1" />
        </material>
      </visual>
        <collision>
        <origin
          xyz="0 0 0"
          rpy="1.57 0 0" />
        <geometry>
          <mesh
            filename="package://edo_description/meshes/cylinder.STL" />
        </geometry>
        </collision>
    </link>
    
    <joint name="joint_7" type="fixed">
        <origin xyz="0 -0.08 0" rpy="0 0 0" />
        <parent link="link_6" />
        <child link="link_enf" />
        <axis xyz="1 0 0" />
    </joint>
    
    <transmission name="trans_joint_1">
        <type>transmission_interface/SimpleTransmission</type>
        <joint name="joint_1">
            <hardwareInterface>hardware_interface/EffortJointInterface</hardwareInterface>
        </joint>
        <actuator name="joint_1_motor">
            <hardwareInterface>hardware_interface/EffortJointInterface</hardwareInterface>
            <mechanicalReduction>1</mechanicalReduction>
        </actuator>
    </transmission>
    <transmission name="trans_joint_2">
        <type>transmission_interface/SimpleTransmission</type>
        <joint name="joint_2">
            <hardwareInterface>hardware_interface/EffortJointInterface</hardwareInterface>
        </joint>
        <actuator name="joint_2_motor">
            <hardwareInterface>hardware_interface/EffortJointInterface</hardwareInterface>
            <mechanicalReduction>1</mechanicalReduction>
        </actuator>
    </transmission>
    <transmission name="trans_joint_3">
        <type>transmission_interface/SimpleTransmission</type>
        <joint name="joint_3">
            <hardwareInterface>hardware_interface/EffortJointInterface</hardwareInterface>
        </joint>
        <actuator name="joint_3_motor">
            <hardwareInterface>hardware_interface/EffortJointInterface</hardwareInterface>
            <mechanicalReduction>1</mechanicalReduction>
        </actuator>
    </transmission>
    <transmission name="trans_joint_4">
        <type>transmission_interface/SimpleTransmission</type>
        <joint name="joint_4">
            <hardwareInterface>hardware_interface/EffortJointInterface</hardwareInterface>
        </joint>
        <actuator name="joint_4_motor">
            <hardwareInterface>hardware_interface/EffortJointInterface</hardwareInterface>
            <mechanicalReduction>1</mechanicalReduction>
        </actuator>
    </transmission>
    <transmission name="trans_joint_5">
        <type>transmission_interface/SimpleTransmission</type>
        <joint name="joint_5">
            <hardwareInterface>hardware_interface/EffortJointInterface</hardwareInterface>
        </joint>
        <actuator name="joint_5_motor">
            <hardwareInterface>hardware_interface/EffortJointInterface</hardwareInterface>
            <mechanicalReduction>1</mechanicalReduction>
        </actuator>
    </transmission>
    <transmission name="trans_joint_6">
        <type>transmission_interface/SimpleTransmission</type>
        <joint name="joint_6">
            <hardwareInterface>hardware_interface/EffortJointInterface</hardwareInterface>
        </joint>
        <actuator name="joint_6_motor">
            <hardwareInterface>hardware_interface/EffortJointInterface</hardwareInterface>
            <mechanicalReduction>1</mechanicalReduction>
        </actuator>
    </transmission>

    <gazebo>
        <plugin name="gazebo_ros_control" filename="libgazebo_ros_control.so">
            <robotNamespace>/</robotNamespace>
            <legacyModeNS>true</legacyModeNS>
        </plugin>
    </gazebo>

    <gazebo reference="base_link">
        <static>true</static>
    </gazebo>

    <gazebo reference="joint_1">
        <disableFixedJointLumping>true</disableFixedJointLumping>
    </gazebo>

    <gazebo reference="joint_2">
        <disableFixedJointLumping>true</disableFixedJointLumping>
    </gazebo>

    <gazebo reference="joint_3">
        <disableFixedJointLumping>true</disableFixedJointLumping>
    </gazebo>

    <gazebo reference="joint_4">
        <disableFixedJointLumping>true</disableFixedJointLumping>
    </gazebo>

    <gazebo reference="joint_5">
        <disableFixedJointLumping>true</disableFixedJointLumping>
    </gazebo>

    <gazebo reference="joint_6">
        <disableFixedJointLumping>true</disableFixedJointLumping>
    </gazebo>

    <gazebo reference="joint_7">
        <disableFixedJointLumping>true</disableFixedJointLumping>
    </gazebo>

</robot>